<?xml version="1.0"?>
<robot name="pumpkin_bot" xmlns:xacro="http://ros.org/wiki/xacro">

  <!-- Define robot constants -->
  <xacro:property name="base_width" value="0.29"/>
  <xacro:property name="base_length" value="0.32"/>
  <xacro:property name="base_height" value="0.59"/>

  <xacro:property name="wheel_radius" value="0.07"/>
  <xacro:property name="wheel_width" value="0.02"/>
  <xacro:property name="wheel_ygap" value="0.01"/>
  <xacro:property name="wheel_zoff" value="0.035"/>
  <xacro:property name="wheel_xoff" value="-0.045"/>

  <xacro:property name="caster_xoff" value="-0.13"/>

   <!-- Define intertial property macros  -->
  <xacro:macro name="box_inertia" params="m w h d">
    <inertial>
      <origin xyz="0 0 0" rpy="${pi/2} 0 ${pi/2}"/>
      <mass value="${m}"/>
      <inertia ixx="${(m/12) * (h*h + d*d)}" ixy="0.0" ixz="0.0" iyy="${(m/12) * (w*w + d*d)}" iyz="0.0" izz="${(m/12) * (w*w + h*h)}"/>
    </inertial>
  </xacro:macro>

  <xacro:macro name="cylinder_inertia" params="m r h">
    <inertial>
      <origin xyz="0 0 0" rpy="${pi/2} 0 0" />
      <mass value="${m}"/>
      <inertia ixx="${(m/12) * (3*r*r + h*h)}" ixy = "0" ixz = "0" iyy="${(m/12) * (3*r*r + h*h)}" iyz = "0" izz="${(m/2) * (r*r)}"/>
    </inertial>
  </xacro:macro>

  <xacro:macro name="sphere_inertia" params="m r">
    <inertial>
      <mass value="${m}"/>
      <inertia ixx="${(2/5) * m * (r*r)}" ixy="0.0" ixz="0.0" iyy="${(2/5) * m * (r*r)}" iyz="0.0" izz="${(2/5) * m * (r*r)}"/>
    </inertial>
  </xacro:macro>

  <!-- Robot Base -->
  <link name="base_link">
    <visual>
      <geometry>
        <box size="${base_length} ${base_width} ${base_height}"/>
      </geometry>
      <origin xyz="0 0 ${base_height/2-.09}" rpy="0 0 0" />
      <material name="Orange">
        <color rgba="1.00 0.647 0.0 1.0"/>
      </material>
    </visual>

    <collision>
      <geometry>
        <box size="${base_length} ${base_width} ${base_height}"/>
      </geometry>
      <origin xyz="0 0 ${base_height/2}" rpy="0 0 0" />
    </collision>

    <xacro:box_inertia m="9" w="${base_width}" d="${base_length}" h="${base_height}"/> 
  </link>
  
  <!-- Robot Footprint -->
  <link name="base_footprint"></link>

  <joint name="base_footprint_joint" type="fixed">
    <parent link="base_footprint"/>
    <child link="base_link"/>
    <origin xyz="0.0 0.0 0.09" rpy="0 0 0"/>
  </joint>

  <!-- Wheels -->
  <xacro:macro name="wheel" params="prefix x_reflect y_reflect">
    <link name="${prefix}_link">
      <visual>
        <origin xyz="0 0 0" rpy="${pi/2} 0 0"/>
        <geometry>
            <cylinder radius="${wheel_radius}" length="${wheel_width}"/>
        </geometry>
        <material name="Black">
          <color rgba="0.0 0.0 0.0 1.0"/>
        </material>
      </visual>

      <collision>
        <origin xyz="0 0 0" rpy="${pi/2} 0 0"/>
        <geometry>
          <cylinder radius="${wheel_radius}" length="${wheel_width}"/>
        </geometry>
      </collision>

      <xacro:cylinder_inertia m="0.5" r="${wheel_radius}" h="${wheel_width}"/>
    </link>

    <joint name="${prefix}_joint" type="continuous">
      <parent link="base_link"/>
      <child link="${prefix}_link"/>
      <origin xyz="${x_reflect*wheel_xoff} ${y_reflect*(base_width/2+wheel_ygap)} ${-wheel_zoff}" rpy="0 0 0"/>
      <axis xyz="0 1 0"/>
    </joint>
  </xacro:macro>

  <xacro:wheel prefix="drivewhl_l" x_reflect="-1" y_reflect="1" />
  <xacro:wheel prefix="drivewhl_r" x_reflect="-1" y_reflect="-1" />
  
  <link name="rear_caster">
    <visual>
      <geometry>
        <sphere radius=".02"/>
      </geometry>
      <material name="Cyan">
        <color rgba="0 1.0 1.0 1.0"/>
      </material>
    </visual>

    <collision>
      <origin xyz="0 0 0" rpy="0 0 0"/>
      <geometry>
        <sphere radius=".02"/>
      </geometry>
    </collision>

    <xacro:sphere_inertia m="0.3" r=".02"/>
  </link>

  <joint name="caster_joint" type="fixed">
    <parent link="base_link"/>
    <child link="rear_caster"/>
    <origin xyz="${caster_xoff} 0.0 -0.09" rpy="0 0 0"/>
  </joint>
  
 <link name="imu_link">
    <visual>
      <geometry>
        <box size="0.03 0.03 0.015"/>
      </geometry>
      <material name="White">
          <color rgba="1.0 1.0 1.0 1.0"/>
        </material>
    </visual>
    
    <collision>
      <geometry>
        <box size="0.03 0.03 0.015"/>
      </geometry>
    </collision>
      
    <xacro:box_inertia m="0.1" w="0.03" d="0.03" h="0.015"/>
  </link>
    
  <joint name="imu_joint" type="fixed">
    <parent link="base_link"/>
    <child link="imu_link"/>
    <origin xyz="-0.14 0 0.23" rpy="0 0 0"/>
  </joint>
  
  <link name="laser">
    <visual>
      <geometry>
        <box size="0.09 0.11 0.07"/>
      </geometry>
      <material name="Black">
          <color rgba="0.0 0.0 0.0 0.0"/>
        </material>
    </visual>
    
    <collision>
      <geometry>
        <box size="0.09 0.11 0.07"/>
      </geometry>
    </collision>
      
    <xacro:box_inertia m="0.1" w="0.09" d="0.11" h="0.07"/>
  </link>
    
  <joint name="lidar_joint" type="fixed">
    <parent link="base_link"/>
    <child link="laser"/>
    <origin xyz="-0.12 0 0.52" rpy="0 0 ${pi/2}"/>
  </joint>

</robot>

